Workbook

Sheet Datos Originales
A1: Empresa | B1: Sucursal | C1: Proveedor | D1: Factura | E1: Fecha Factura | F1: Fecha Poliza | G1: Fecha Envío | H1: Total | I1: Moneda | J1: Tipo Cambio | K1: Total MX | L1: Insumo | M1: Cantidad | N1: Precio | O1: Descuento | P1: Total | Q1: Total MX | R1: Tipo | S1: Familia | T1: SubFamilia | U1: Folio | V1: OC | W1: REQ | X1: SC | Y1: Departamento | Z1: Solicitante | AA1: Grupo Centro de Costo | AB1: Centro Costo | AC1: K.M. | AD1: Colaborador | AE1: Estatus | AF1: CC OC | AG1: Observaciones OC | AH1: Subtotal OC | AI1: Descuento OC | AJ1: IVA OC | AK1: Gastos Envío OC | AL1: Total OC | AM1: Cuenta Contable 1 | AN1: Cuenta Contable 2 | AO1: Cuenta Contable 3 | AP1: Cuenta Contable 4 | AQ1: Cuenta Contable 5 | AR1: Cuenta Contable 6 | AS1: Cuenta Contable 7 | AT1: Cuenta Contable 8 | AU1: Cuenta Contable 9 | AV1: Cuenta Contable 10 | AW1: Cuenta Contable 11 | AX1: Cuenta Contable 12 | AY1: Cuenta Contable 13 | AZ1: Cuenta Contable 14 | BA1: Cuenta Contable 15 | BB1: Cuenta Contable 16 | BC1: Cuenta Contable 17
A2: PETROPLAZAS | B2: Alamos | C2: FORMULA 100 SA DE CV | D2: A4860 | E2: 01/06/2026 | F2: 01/06/2026 | G2: 01/06/2026 | H2: 288.84 | I2: Pesos (MXN) | J2: 1 | K2: 288.84 | L2: SERVICIO DE RENTA AVANZADO DISPOSITIVO 3NW | M2: 1 | N2: 249 | P2: 249 | Q2: 249 | R2: SERVICIO | S2: Servicios | T2: Servicios | U2: SRV0000068 | V2: 73114 | W2: 66408 | X2: 60214 | Y2: ADMINISTRACION | Z2: CRISTOBAL IBARRA MANZANO | AA2: ES_Alamos | AB2: AUTOMOVIL - AU-151 | AE2: PAGADA | AF2: AUTOMOVIL - AU-151 | AG2: Movimiento generado en automático por sistema. Proceso de Carga Masiva de Facturas | AH2: 249.00 | AI2: 0.00 | AJ2: 39.84 | AK2: 0.00 | AL2: 288.84 | AM2: 50299040046 | AN2: 12101030000 | AO2: 20101021500
A3: PETROPLAZAS | B3: Petroplazas Corporativo | C3: ARK 21 | D3: 64F6E70 | E3: 01/06/2026 | F3: 01/06/2026 | G3: 01/06/2026 | H3: 836484.95 | I3: Pesos (MXN) | J3: 1 | K3: 836484.95 | L3: CONSTRUCCION - SERVICIO DE CONSTRUCCION | M3: 0.045860264 | N3: 15724020.1 | P3: 721107.7129273064 | Q3: 721107.712927 | R3: SERVICIO | S3: Servicios | T3: Servicios | U3: SRV0005503 | V3: 70783 | W3: 63973 | X3: 58132 | Y3: COMPRAS | Z3: HUGO JAIME LIZARRAGA CARRILLO | AA3: ES_Corporativo | AB3: CC ADMINISTRACION | AC3: 0 | AE3: PAGADA | AF3: CC ADMINISTRACION | AG3: PROYECTO DE CONSTRUCCION DE ESTACION COLON. CFDI I01 CONSTRUCCION | AH3: 15,724,020.10 | AI3: 0.00 | AJ3: 2,515,843.22 | AK3: 0.00 | AL3: 18,239,863.32 | AM3: _CUA-DRE--000000 | AN3: 12101030000 | AO3: 20101021500
A4: PETROPLAZAS | B4: Rosario | C4: Equipos Industriales del Noroeste SA de CV | D4: FA23246 | E4: 01/06/2026 | F4: 01/06/2026 | G4: 01/06/2026 | H4: 4572.86 | I4: Pesos (MXN) | J4: 1 | K4: 4572.86 | L4: PISTOLA AUTOMATICA OPW 3/4" NEGRO | N4: 1656.06 | R4: ALMACEN | S4: Herramientas y Utiles | T4: Accesorios | U4: E000000121 | V4: 73208 | X4: 60217 | Z4: Maria Isabel Vega Gaxiola | AE4: PAGADA | AF4: Estatus Surtido | AG4: COMPRA POR MATERIAL PARA STOK APOYOA DISPENSARIOS ESTACION ROSARIO, MAYO 2026. Nota; Facturar a inicios de junio por favor. ENTREGAR EN CEDIS MAZATLAN CON ISABLE VEGA. | AH4: 3,942.12 | AI4: 0.00 | AJ4: 630.74 | AK4: 0.00 | AL4: 4,572.86 | AM4: 20101021501 | AN4: 12101030000 | AO4: 20101021500
A5: PETROPLAZAS | B5: Fatima | C5: FORMULA 100 SA DE CV | D5: A4861 | E5: 01/06/2026 | F5: 01/06/2026 | G5: 01/06/2026 | H5: 288.84 | I5: Pesos (MXN) | J5: 1 | K5: 288.84 | L5: SERVICIO DE RENTA AVANZADO DISPOSITIVO 3NW | M5: 1 | N5: 249 | P5: 249 | Q5: 249 | R5: SERVICIO | S5: Servicios | T5: Servicios | U5: SRV0000040 | V5: 73115 | W5: 66409 | X5: 60215 | Y5: ADMINISTRACION | Z5: CRISTOBAL IBARRA MANZANO | AA5: ES_Fatima | AB5: AUTOMOVIL AU-131 | AE5: PAGADA | AF5: AUTOMOVIL AU-131 | AG5: Movimiento generado en automático por sistema. Proceso de Carga Masiva de Facturas | AH5: 249.00 | AI5: 0.00 | AJ5: 39.84 | AK5: 0.00 | AL5: 288.84 | AM5: 50299040046 | AN5: 12101030000 | AO5: 20101021500
A6: PETROPLAZAS | B6: Escuinapa | C6: Equipos Industriales del Noroeste SA de CV | D6: FA23247 | E6: 01/06/2026 | F6: 01/06/2026 | G6: 01/06/2026 | H6: 3842.06 | I6: Pesos (MXN) | J6: 1 | K6: 3842.06 | L6: PISTOLA AUTOMATICA OPW 3/4" NEGRO | N6: 1656.06 | R6: ALMACEN | S6: Herramientas y Utiles | T6: Accesorios | U6: E000000182 | V6: 73121 | X6: 60211 | Z6: Maria Isabel Vega Gaxiola | AE6: PAGADA | AF6: Estatus Surtido | AG6: COMPRA POR PISTOLA PARA DESP. GASOL. NEGRA DE 3/4" 11-B OPW SOLICTADAS PARA ESTACION ESCUINAPA, MAYO 2026. Nota, Facturar a inicios de junio ENTREGAR EN CEDIS MAZATLAN CON ISABEL VEGA. | AH6: 3,312.12 | AI6: 0.00 | AJ6: 529.94 | AK6: 0.00 | AL6: 3,842.06 | AM6: 20101021501 | AN6: 12101030000 | AO6: 20101021500
A7: PETROPLAZAS | B7: AEROPUERTO | C7: Electrica Valdez SA de CV | D7: M00646230 | E7: 01/06/2026 | F7: 01/06/2026 | G7: 01/06/2026 | H7: 1293.86 | I7: Pesos (MXN) | J7: 1 | K7: 1293.86 | L7: TUBO LED T8 18W BASE ALUMINIO | N7: 33 | R7: ALMACEN | S7: Ferreteria | T7: Varios | U7: E000000282 | V7: 73287 | W7: 66290 | X7: 60221 | Y7: OPERACIONES | Z7: Maria Isabel Vega Gaxiola | AA7: ES_Aeropuerto | AB7: ESTACION AEROPUERTO | AE7: PAGADA | AF7: ESTACION AEROPUERTO | AG7: COMPRA POR 6 TUBO LED 36W T8 Y Y 10 TUBO LED 18W T8 120cm SOLICITADOS PARA ESTACION AEROPUERTO, JUNIO 2026. ENTREGAR EN CEDIS MAZATLAN CON ISABEL VEGA. | AH7: 1,115.40 | AI7: 0.00 | AJ7: 178.46 | AK7: 0.00 | AL7: 1,293.86 | AM7: 20101021501 | AN7: 12101030000 | AO7: 20101021500
A8: PETROPLAZAS | B8: La Colorada | C8: COMERCIALIZADORA SANITARIA, S.A. DE C.V. | D8: MAZ4892 | E8: 02/06/2026 | F8: 02/06/2026 | G8: 02/06/2026 | H8: 4582 | I8: Pesos (MXN) | J8: 1 | K8: 4582 | L8: JABON LIQUIDO PARA MANOS | N8: 41.4 | R8: ALMACEN | S8: Artículos de Limpieza | T8: Artículos de Limpieza | U8: E000000183 | V8: 73302 | W8: 66420 | X8: 60331 | Y8: OPERACIONES GASOLINERAS | Z8: Diego Alejandro Estrada Ramos | AA8: ES_LA_COLORADA | AB8: BAÑOS PARA COLABORADORES. | AE8: PAGADA | AF8: OFICINAS ADMINISTRATIVAS. | AG8: FAVOR DE ENTREGAR EN ESTACION LA COLORADA CON EL SUPERVISOR AL DOMICILIO CALLE LATERAL CARRETERA SN, COL. NUEVO HERMOSILLO, HERMOSILLO, SONORA, CP. 83296. MATERIAL DE LIMPIEZA DEL MES DE JUNIO 2026. | AH8: 3,950.00 | AI8: 0.00 | AJ8: 632.00 | AK8: 0.00 | AL8: 4,582.00 | AM8: 20101021501 | AN8: 12101030000 | AO8: 20101021500
A9: PETROPLAZAS | B9: Fatima | C9: FRANCISCO JAVIER RAMIREZ HERNANDEZ | D9: A6054 | E9: 01/06/2026 | F9: 02/06/2026 | G9: 02/06/2026 | H9: 2673.65 | I9: Pesos (MXN) | J9: 1 | K9: 2673.65 | L9: CAMARA DE SEGURIDAD PARA INTERIOR | N9: 768.29 | R9: ALMACEN | S9: Equipo de Computo | T9: Camaras | U9: E000000119 | V9: 73327 | W9: 66383 | X9: 60354 | Y9: OPERACIONES GASOLINERAS | Z9: Diego Alejandro Estrada Ramos | AA9: ES_Fatima | AB9: Estacion Fatima | AE9: PAGADA | AF9: Estacion Fatima | AG9: CORRESPONDE A LA FACTURA A6054. CAMARA DE SEGURIDAD Y ADITAMIENTO EN ESTACION FATIMA. | AH9: 2,304.87 | AI9: 0.00 | AJ9: 368.78 | AK9: 0.00 | AL9: 2,673.65 | AM9: 20101021501 | AN9: 12101030000 | AO9: 20101021500
A10: PETROPLAZAS | B10: Petroplazas Corporativo | C10: Aguilar Hernandez Ana Guadalupe | D10: F701219 | E10: 01/06/2026 | F10: 02/06/2026 | G10: 02/06/2026 | H10: 206025.46 | I10: Pesos (MXN) | J10: 1 | K10: 206025.46 | L10: PRESTACION DE SERVICIOS | M10: 1 | N10: 216110.7 | P10: 216110.7 | Q10: 216110.7 | R10: SERVICIO | S10: Servicios | T10: Servicios | U10: SRV0005507 | V10: 73376 | W10: 66548 | X10: 60376 | Y10: CONTABILIDAD | Z10: ELIZABETH GUADALUPE ARROYO PERAZA | AA10: ES_Corporativo | AB10: GASTOS GENERALES | AE10: PAGADA | AF10: GASTOS GENERALES | AG10: PAGO DE LA FACT. 19 POR EL ARRENDAMIENTO DE TERRENO DE ESTACION EL DIEZ, (LA O.C. SE HIZO POR 12 MESES, LOS CUALES SE IRAN PAGANDO MES A MES). PROGRAMAR A PAGO PARA EL 04/06/2026. | AH10: 2,593,328.40 | AI10: 0.00 | AJ10: 414,932.54 | AK10: 0.00 | AL10: 2,472,305.54 | AM10: 50299040023 | AN10: 12101030000 | AO10: 22201050000 | AP10: 22201020000 | AQ10: 20101021500
A11: PETROPLAZAS | B11: CEDIS Mazatlán | C11: JOSHUA ALBERTO TIRADO ROMERO | D11: 462FC | E11: 02/06/2026 | F11: 02/06/2026 | G11: 02/06/2026 | H11: 78648 | I11: Pesos (MXN) | J11: 1 | K11: 78648 | L11: SERVICIO DE INTERNET | M11: 1 | N11: 2900 | P11: 2900 | Q11: 2900 | R11: SERVICIO | S11: Servicios | T11: Servicios | U11: SRV0000604 | V11: 73381 | W11: 66558 | X11: 60379 | Y11: INFRAESTRUCTURA TECNOLOGICA | Z11: JUAN CARLOS MORENO OSUNA | AA11: EST_EL_CONCHI | AB11: ES_El_Conchi | AE11: PAGADA | AF11: Escuinapa | AG11: SERVICIO RED JOSHUA SITIO MAZATLAN, JUNIO 2026 | AH11: 67,800.00 | AI11: 0.00 | AJ11: 10,848.00 | AK11: 0.00 | AL11: 78,648.00 | AM11: 50299040042 | AN11: 12101030000 | AO11: 20101021500
A12: PETROPLAZAS | B12: Petroplazas Corporativo | C12: Juan Pablo Ramos Velarde | D12: I40 | E12: 01/06/2026 | F12: 02/06/2026 | G12: 02/06/2026 | H12: 11475 | I12: Pesos (MXN) | J12: 1 | K12: 11475 | L12: SERVICIO DE DESARROLLO DE SOFTWARE | M12: 1 | N12: 10000 | P12: 10000 | Q12: 10000 | R12: SERVICIO | S12: Servicios | T12: Servicios | U12: SRV0005504 | V12: 73329 | W12: 66518 | X12: 60356 | Y12: COMPRAS | Z12: HUGO JAIME LIZARRAGA CARRILLO | AA12: ES_Corporativo | AB12: CC ADMINISTRACION | AC12: 0 | AE12: PAGADA | AF12: CC ADMINISTRACION | AG12: CORRESPONDE A LA FACTURA 40. SERVICIO DE MANTENIMIENTO Y DESARROLLO DE SOFTWARE DE CORPORATIVO DIVISION GASOLINERAS. | AH12: 10,000.00 | AI12: 0.00 | AJ12: 1,600.00 | AK12: 0.00 | AL12: 11,475.00 | AM12: 50299040021 | AN12: 12101030000 | AO12: 22201210000 | AP12: 20101021500
A13: PETROPLAZAS | B13: CEDIS Culiacán | C13: GABRIELA DE JESUS RAMIREZ LOAIZA | D13: E018C998 | E13: 01/06/2026 | F13: 02/06/2026 | G13: 02/06/2026 | H13: 13936.94 | I13: Pesos (MXN) | J13: 1 | K13: 13936.94 | L13: PANTALON PARA DESPACHADORES AZUL 32 | N13: 357.22 | R13: ALMACEN | S13: Uniformes | T13: PANTALONES | U13: E000000270 | V13: 73174 | X13: 60046 | Z13: Diego Alejandro Estrada Ramos | AE13: PAGADA | AF13: Estatus Surtido | AG13: FAVOR DE ENTREGAR EN CEDIS CULIACAN CON DIEGO. PANTALON DESPACHADOR AZUL PARA STOCK DE ZONA CLN, ANGOSTURA Y NORTE. | AH13: 12,145.48 | AI13: 0.00 | AJ13: 1,943.28 | AK13: 0.00 | AL13: 13,936.94 | AM13: 20101021501 | AN13: 12101030000 | AO13: 22201020000 | AP13: 20101021500
A14: PETROPLAZAS | B14: CEDIS Culiacán | C14: GABRIELA DE JESUS RAMIREZ LOAIZA | D14: B0C2F997 | E14: 01/06/2026 | F14: 02/06/2026 | G14: 02/06/2026 | H14: 13238.48 | I14: Pesos (MXN) | J14: 1 | K14: 13238.48 | L14: PANTALON PARA DESPACHADORES AZUL 40 | N14: 384.56 | R14: ALMACEN | S14: Uniformes | T14: PANTALONES | U14: E000000271 | V14: 73179 | X14: 60048 | Z14: Diego Alejandro Estrada Ramos | AE14: PAGADA | AF14: Estatus Surtido | AG14: FAVOR DE ENTREGAR EN CEDIS CULIACAN CON DIEGO. PANTALON DESPACHADOR AZUL PARA STOCK DE ZONA CLN, ANGOSTURA Y NORTE. | AH14: 11,536.80 | AI14: 0.00 | AJ14: 1,845.89 | AK14: 0.00 | AL14: 13,238.48 | AM14: 20101021501 | AN14: 12101030000 | AO14: 22201020000 | AP14: 20101021500
A15: PETROPLAZAS | B15: Revolucion | C15: ARTURO TRINIDAD SANDOVAL GONZALEZ | D15: A1549 | E15: 02/06/2026 | F15: 03/06/2026 | G15: 03/06/2026 | H15: 2366.4 | I15: Pesos (MXN) | J15: 1 | K15: 2366.4 | L15: JALADOR DE AGUA DE PISO | N15: 185 | R15: ALMACEN | S15: Artículos de Limpieza | T15: Artículos de Limpieza | U15: E000000153 | V15: 73297 | W15: 66450 | X15: 60303 | Y15: OPERACIONES GASOLINERAS | Z15: Diego Alejandro Estrada Ramos | AA15: ES_Revolucion | AB15: Baños publicos | AE15: PAGADA | AF15: Baños publicos | AG15: FAVOR DE ENTREGAR EN ESTACION REVOLUCION CON EL SUPERVISOR AL DOMICILIO BLVD. LUIS DONAL. COLOSIO NO. 615, COL. REVOLUCION MEXICANA, GUASAVE, SINALOA, C.P. 81016. MATERIAL DE LIMPIEZA DEL MES DE JUNIO 2026. | AH15: 2,040.00 | AI15: 0.00 | AJ15: 326.40 | AK15: 0.00 | AL15: 2,366.40 | AM15: 20101021501 | AN15: 12101030000 | AO15: 20101021500
A16: PETROPLAZAS | B16: CEDIS Culiacán | C16: JOSHUA ALBERTO TIRADO ROMERO | D16: CCCEC | E16: 03/06/2026 | F16: 03/06/2026 | G16: 03/06/2026 | H16: 19200 | I16: Pesos (MXN) | J16: 1 | K16: 19200 | L16: SERVICIO DE INTERNET | M16: 1 | N16: 4137.93 | P16: 4137.93 | Q16: 4137.93 | R16: SERVICIO | S16: Servicios | T16: Servicios | U16: SRV0000460 | V16: 73405 | W16: 66616 | X16: 60423 | Y16: INFRAESTRUCTURA TECNOLOGICA | Z16: JUAN CARLOS MORENO OSUNA | AA16: PERICOS | AB16: PERICOS | AE16: PAGADA | AF16: CUAUHTEMOC | AG16: SERVICIO RED JOSHUA SITIO CULIACAN, JUNIO 2026 | AH16: 16,551.72 | AI16: 0.00 | AJ16: 2,648.28 | AK16: 0.00 | AL16: 19,200.00 | AM16: 50299040042 | AN16: 12101030000 | AO16: 20101021500
A17: PETROPLAZAS | B17: La Colorada | C17: PETRO SMART COMBUSTIBLES, S.A. DE C.V. | D17: GHMO004237 | E17: 01/06/2026 | F17: 03/06/2026 | G17: 03/06/2026 | H17: 1277.48 | I17: Pesos (MXN) | J17: 1 | K17: 1277.48 | L17: GAS LP | M17: 115.4002 | N17: 9.5431 | P17: 1101.27564862 | Q17: 1101.275649 | R17: SERVICIO | S17: Gastos diversos | T17: Varios (Gastos Diversos) | U17: SRV0000194 | V17: 73339 | W17: 66537 | X17: 60372 | Y17: COMPRAS | Z17: HUGO JAIME LIZARRAGA CARRILLO | AA17: ES_LA_COLORADA | AB17: ESTACION LA COLORADA | AE17: PAGADA | AF17: ESTACION LA COLORADA | AG17: CORRESPONDE A LA FACTURA GHMO004237. SERVICIO DE GAS LP PARA AREA DE PENSION DE ESTACION LA COLORADA. | AH17: 1,101.28 | AI17: 0.00 | AJ17: 176.20 | AK17: 0.00 | AL17: 1,277.48 | AM17: 50299040017 | AN17: 12101030000 | AO17: 20101021500
A18: PETROPLAZAS | B18: Forjadores | C18: JOSHUA ALBERTO TIRADO ROMERO | D18: 72C4F | E18: 03/06/2026 | F18: 03/06/2026 | G18: 03/06/2026 | H18: 4800 | I18: Pesos (MXN) | J18: 1 | K18: 4800 | L18: SERVICIO DE INTERNET | M18: 1 | N18: 4137.93 | P18: 4137.93 | Q18: 4137.93 | R18: SERVICIO | S18: Servicios | T18: Servicios | U18: SRV0000296 | V18: 73407 | W18: 66620 | X18: 60427 | Y18: INFRAESTRUCTURA TECNOLOGICA | Z18: JUAN CARLOS MORENO OSUNA | AA18: ES_FORJADORES | AB18: D. ADMINISTRACION | AE18: PAGADA | AF18: D. ADMINISTRACION | AG18: SERVICIO RED JOSHUA SITIO PAZ, JUNIO 2026 | AH18: 4,137.93 | AI18: 0.00 | AJ18: 662.07 | AK18: 0.00 | AL18: 4,800.00 | AM18: 50299040042 | AN18: 12101030000 | AO18: 20101021500
A19: PETROPLAZAS | B19: SANTA ROSA | C19: Operadora Polar SA de CV | D19: MZF445034 | E19: 01/06/2026 | F19: 03/06/2026 | G19: 03/06/2026 | H19: 676.05 | I19: Pesos (MXN) | J19: 1 | K19: 676.05 | L19: BOLSA TRANSPARENTE 18 CMS X 26 CMS (CAPACIDAD 1 KG) | N19: 59 | R19: ALMACEN | S19: Gastos diversos | T19: Varios (Gastos Diversos) | U19: E000000138 | V19: 73250 | W19: 66217 | X19: 60174 | Y19: OPERACIONES GASOLINERAS | Z19: Maria Isabel Vega Gaxiola | AA19: ES_SANTA_ROSA | AB19: BAÑOS AL PÚBLICO | AE19: PAGADA | AF19: BAÑOS AL PÚBLICO | AG19: FAVOR DE ENTREGAR EN ESTACION SANTA ROSA CON EL SUPERVISOR. MATERIAL DE LIMPIEZA DEL MES DE JUNIO 2026. | AH19: 582.80 | AI19: 0.00 | AJ19: 93.25 | AK19: 0.00 | AL19: 676.05 | AM19: 50299040042 | AN19: 12101030000 | AO19: 20101021500
A20: PETROPLAZAS | B20: CEDIS Mazatlán | C20: DIANA ANGELICA LOPEZ MACHADO | D20: 20251611 | E20: 01/06/2026 | F20: 03/06/2026 | G20: 03/06/2026 | H20: 17121.6 | I20: Pesos (MXN) | J20: 1 | K20: 17121.6 | L20: PANTALON DE VESTIR CABALLERO 36 X 32 | N20: 369 | R20: ALMACEN | S20: Uniformes | T20: PANTALONES | U20: E000000461 | V20: 73167 | X20: 59973 | Z20: Maria Isabel Vega Gaxiola | AE20: PAGADA | AF20: Estatus Surtido | AG20: FAVOR DE ENTREGAR EN CEDIS MAZATLAN CON ISABEL. PANTALON DE VESTIR CABALLERO AZUL MARINO PARA STOCK DE CEDIS MAZATLAN. | AH20: 14,760.00 | AI20: 0.00 | AJ20: 2,361.60 | AK20: 0.00 | AL20: 17,121.60 | AM20: 20101021501 | AN20: 12101030000 | AO20: 20101021500
A21: PETROPLAZAS | B21: CEDIS Mazatlán | C21: HEAT COMMERCIAL S.A. DE C.V. | D21: F68961 | E21: 03/06/2026 | F21: 03/06/2026 | G21: 03/06/2026 | H21: 3990.4 | I21: Pesos (MXN) | J21: 1 | K21: 3990.4 | L21: GORRA AMARILLA/REY PARA DESPACHADORES (LOGO REDPETROIL) | N21: 43 | R21: ALMACEN | S21: Uniformes | T21: Gorra | U21: E000000462 | V21: 73372 | X21: 59972 | Z21: Maria Isabel Vega Gaxiola | AE21: PAGADA | AF21: Estatus Surtido | AG21: FAVOR DE ENTREGAR EN CEDIS MAZATLAN CON ISABEL AL DOMICILIO AZALEA NO. 4901, COL. RICARDO FLORES MAGON, C.P. 82190, MAZATLAN, SINALOA. GORRA ACRILANA AMARILLO / REY C/BORDADO FTE REDPETROIL PARA STOCK DE CEDIS MAZATLAN PARA ESTACIONES SABALO, AEROPUERTO, CONCORDIA, HABAL, 12 DE MAYO, FORESTA, URBIVILLA, GRIJALVA, ROSARIO Y ESCUINAPA. | AH21: 3,440.00 | AI21: 0.00 | AJ21: 550.40 | AK21: 0.00 | AL21: 3,990.40 | AM21: 20101021501 | AN21: 12101030000 | AO21: 20101021500
A22: PETROPLAZAS | B22: SANTA ROSA | C22: JORGE LUIS LIZARRAGA GARATE | D22: BCR672 | E22: 01/06/2026 | F22: 03/06/2026 | G22: 03/06/2026 | H22: 503.11 | I22: Pesos (MXN) | J22: 1 | K22: 503.11 | L22: AROMATIZANTE PARA PISO | N22: 13.2145 | R22: ALMACEN | S22: Artículos de Limpieza | T22: Artículos de Limpieza | U22: E000000139 | V22: 73252 | W22: 66217 | X22: 60174 | Y22: OPERACIONES GASOLINERAS | Z22: Maria Isabel Vega Gaxiola | AA22: ES_SANTA_ROSA | AB22: BAÑOS AL PÚBLICO | AE22: PAGADA | AF22: BAÑOS AL PÚBLICO | AG22: FAVOR DE ENTREGAR EN ESTACION SANTA ROSA CON EL SUPERVISOR. MATERIAL DE LIMPIEZA DEL MES DE JUNIO 2026. | AH22: 438.44 | AI22: 0.00 | AJ22: 70.15 | AK22: 0.00 | AL22: 503.11 | AM22: 20101021501 | AN22: 12101030000 | AO22: 22201020000 | AP22: 20101021500
A23: PETROPLAZAS | B23: Alamos | C23: Jose Carmen Montaño Aramburo | D23: FDF0430176 | E23: 01/06/2026 | F23: 03/06/2026 | G23: 03/06/2026 | H23: 636.84 | I23: Pesos (MXN) | J23: 1 | K23: 636.84 | L23: CARGADOR PARA LAPTOP | N23: 549 | R23: ALMACEN | S23: Equipo de Computo | T23: Accesorios de cómputo | U23: E000000128 | V23: 73301 | W23: 65562 | X23: 59484 | Y23: OPERACIONES | Z23: Diego Alejandro Estrada Ramos | AA23: CC Empleados | AB23: CC Jose Carlos Valdez Nuñez | AE23: PAGADA | AF23: CC Jose Carlos Valdez Nuñez | AG23: FAVOR DE ENTREGAR EN CEDIS MAZATLAN CON ISABEL. CARGADOR LENOVO ADL45WCC PARA LAPTOP LENOVO IDEAPAD 320 DE ING. JOSE CARLOS JEFE DE PISO ZONA NORTE. | AH23: 549.00 | AI23: 0.00 | AK23: 0.00 | AL23: 549.00 | AM23: 20101021501 | AN23: 12101030000 | AO23: 20101021500
A24: PETROPLAZAS | B24: Sabalo | C24: Electrica Valdez SA de CV | D24: M00646285 | E24: 01/06/2026 | F24: 03/06/2026 | G24: 03/06/2026 | H24: 4654.85 | I24: Pesos (MXN) | J24: 1 | K24: 4654.85 | L24: CABLE USO RUDO 3 X 12 | N24: 40.128 | R24: ALMACEN | S24: Herramientas y Utiles | T24: Cables | U24: E000000207 | V24: 73337 | W24: 66527 | X24: 60358 | Y24: COMPRAS | Z24: Maria Isabel Vega Gaxiola | AA24: ES_Sabalo | AB24: CC OPERACIONES | AC24: 0 | AE24: PAGADA | AF24: CC OPERACIONES | AG24: CORRESPONDE A LA FACTURA M-00646285. MATERIAL ELECTRICO PARA ESTACION SABALO. | AH24: 4,012.80 | AI24: 0.00 | AJ24: 642.05 | AK24: 0.00 | AL24: 4,654.85 | AM24: 20101021501 | AN24: 12101030000 | AO24: 20101021500
A25: PETROPLAZAS | B25: SANTA ROSA | C25: Operadora Polar SA de CV | D25: MZF445096 | E25: 02/06/2026 | F25: 03/06/2026 | G25: 03/06/2026 | H25: 435 | I25: Pesos (MXN) | J25: 1 | K25: 435 | L25: EMPLAYE TRANSPARENTE | N25: 125 | R25: ALMACEN | S25: Ferreteria | T25: Ferreteria | U25: E000000141 | V25: 73377 | W25: 66553 | X25: 60378 | Y25: OPERACIONES GASOLINERAS | Z25: Maria Isabel Vega Gaxiola | AA25: ES_SANTA_ROSA | AB25: CC OPERACIONES | AC25: 0 | AE25: PAGADA | AF25: CC OPERACIONES | AG25: CORRESPONDE A LA FACTURA MZF445096. EMPLAYE PARA ESTACION SANTA ROSA. | AH25: 375.00 | AI25: 0.00 | AJ25: 60.00 | AK25: 0.00 | AL25: 435.00 | AM25: 20101021501 | AN25: 12101030000 | AO25: 20101021500
A26: PETROPLAZAS | B26: La Foresta | C26: Operadora Polar SA de CV | D26: MZF445025 | E26: 01/06/2026 | F26: 03/06/2026 | G26: 03/06/2026 | H26: 1912.61 | I26: Pesos (MXN) | J26: 1 | K26: 1912.61 | L26: BOLSA DE CAMISETA JUMBO | N26: 41 | R26: ALMACEN | S26: Artículos de Limpieza | T26: Artículos de Limpieza | U26: E000000180 | V26: 73253 | W26: 66249 | X26: 60165 | Y26: OPERACIONES | Z26: Maria Isabel Vega Gaxiola | AA26: ES_La Foresta | AB26: CC OPERACIONES | AC26: 0 | AE26: PAGADA | AF26: CC OPERACIONES | AG26: FAVOR DE ENTREGAR EN ESTACION FORESTA CON EL SUPERVISOR. MATERIAL DE LIMPIEZA DEL MES DE JUNIO 2026. | AH26: 1,648.80 | AI26: 0.00 | AJ26: 263.81 | AK26: 0.00 | AL26: 1,912.61 | AM26: 20101021501 | AN26: 12101030000 | AO26: 20101021500
A27: PETROPLAZAS | B27: Fatima | C27: ARTURO TRINIDAD SANDOVAL GONZALEZ | D27: A1551 | E27: 02/06/2026 | F27: 03/06/2026 | G27: 03/06/2026 | H27: 2619.28 | I27: Pesos (MXN) | J27: 1 | K27: 2619.28 | L27: AROMATIZANTE PARA PISO | N27: 19.5 | R27: ALMACEN | S27: Artículos de Limpieza | T27: Artículos de Limpieza | U27: E000000123 | V27: 73293 | W27: 66451 | X27: 60306 | Y27: OPERACIONES GASOLINERAS | Z27: Diego Alejandro Estrada Ramos | AA27: ES_Fatima | AB27: Baños publicos | AE27: PAGADA | AF27: Baños publicos | AG27: FAVOR DE ENTREGAR EN ESTACION FATIMA CON EL SUPERVISOR AL DOMICILIO ANGEL FLORES NTE. 983 COL. CENTRO, AHOME LOS MOCHIS, SINALOA, C.P. 81200. MATERIAL DE LIMPIEZA DEL MES DE JUNIO 2026. | AH27: 2,258.00 | AI27: 0.00 | AJ27: 361.28 | AK27: 0.00 | AL27: 2,619.28 | AM27: 20101021501 | AN27: 12101030000 | AO27: 20101021500
A28: PETROPLAZAS | B28: Alamos | C28: ARTURO TRINIDAD SANDOVAL GONZALEZ | D28: A1550 | E28: 02/06/2026 | F28: 03/06/2026 | G28: 03/06/2026 | H28: 2729.48 | I28: Pesos (MXN) | J28: 1 | K28: 2729.48 | L28: PAPEL HIGIENICO JUMBO BLANCO | N28: 32 | R28: ALMACEN | S28: Artículos de Limpieza | T28: Artículos de Limpieza | U28: E000000130 | V28: 73289 | W28: 66435 | X28: 60257 | Y28: OPERACIONES GASOLINERAS | Z28: Diego Alejandro Estrada Ramos | AA28: ES_Alamos | AB28: Baños publicos | AE28: PAGADA | AF28: Baños publicos | AG28: FAVOR DE ENTREGAR EN ESTACION ALAMOS CON EL SUPERVISOR AL DOMICILIO BLVD. MACARIO GAXIOLA NO. 1500 SUR, FRACC. LOS ALAMOS 1, AHOME LOS MOCHIS, SINALOA, C.P. 81280. MATERIAL DE LIMPIEZA DEL MES DE JUNIO 2026. | AH28: 2,353.00 | AI28: 0.00 | AJ28: 376.48 | AK28: 0.00 | AL28: 2,729.48 | AM28: 20101021501 | AN28: 12101030000 | AO28: 20101021500
A29: PETROPLAZAS | B29: Petroplazas Corporativo | C29: JOSHUA ALBERTO TIRADO ROMERO | D29: 2C6A1 | E29: 03/06/2026 | F29: 03/06/2026 | G29: 03/06/2026 | H29: 3712 | I29: Pesos (MXN) | J29: 1 | K29: 3712 | L29: SERVICIO DE INTERNET | M29: 1 | N29: 3200 | P29: 3200 | Q29: 3200 | R29: SERVICIO | S29: Servicios | T29: Servicios | U29: SRV0005508 | V29: 73406 | W29: 66619 | X29: 60426 | Y29: INFRAESTRUCTURA TECNOLOGICA | Z29: JUAN CARLOS MORENO OSUNA | AA29: ES_Corporativo | AB29: CC Administracion | AE29: PAGADA | AF29: CC Administracion | AG29: SERVICIO RED JOSHUA SITIO NAS, JUNIO 2026 | AH29: 3,200.00 | AI29: 0.00 | AJ29: 512.00 | AK29: 0.00 | AL29: 3,712.00 | AM29: 50299040042 | AN29: 12101030000 | AO29: 20101021500
A30: PETROPLAZAS | B30: ALHUEY1 | C30: Equipos Industriales del Noroeste SA de CV | D30: FC26295 | E30: 02/06/2026 | F30: 03/06/2026 | G30: 03/06/2026 | H30: 1025.97 | I30: Pesos (MXN) | J30: 1 | K30: 1025.97 | L30: Palanca de mecanismo | N30: 294.82 | R30: ALMACEN | S30: Gastos diversos | T30: Varios (Gastos Diversos) | U30: E000000195 | V30: 73211 | W30: 61685 | X30: 56134 | Y30: OPERACIONES | Z30: Diego Alejandro Estrada Ramos | AA30: ES_ALHUEY1 | AB30: Estacion Alhuey 1 | AE30: PAGADA | AF30: Estacion Alhuey 1 | AG30: COMPRA DE 3 PATITAS (FUSIBLE) PARA VALVULA SHUT OFF PARA ESTACION ALHUEY 1. (ENTREGAR EN ALMACEN DE REFACCIONES DE CAMPO EL DIEZ). Y FACTURAR CON 1 DE JUNIO. | AH30: 884.46 | AI30: 0.00 | AJ30: 141.51 | AK30: 0.00 | AL30: 1,025.97 | AM30: 20101021501 | AN30: 12101030000 | AO30: 20101021500
A31: PETROPLAZAS | B31: Dos Valles | C31: ARTURO TRINIDAD SANDOVAL GONZALEZ | D31: A1548 | E31: 02/06/2026 | F31: 03/06/2026 | G31: 03/06/2026 | H31: 1137.96 | I31: Pesos (MXN) | J31: 1 | K31: 1137.96 | L31: CEPILLO PARA WC CON BASE | N31: 85 | R31: ALMACEN | S31: Artículos de Limpieza | T31: Artículos de Limpieza | U31: E000000131 | V31: 73295 | W31: 66415 | X31: 60262 | Y31: OPERACIONES | Z31: Diego Alejandro Estrada Ramos | AA31: ES_Dos Valles | AB31: Baños publicos | AE31: PAGADA | AF31: Baños publicos | AG31: FAVOR DE ENTREGAR EN ESTACION DOS VALLE CON EL SUPERVISOR AL DOMICILIO BLVD. LUIS DONALDO COLOSIO NO. 264, COL. OCORO, GUASAVE, SINALOA, C.P. 81010. MATERIAL DE LIMPIEZA DEL MES DE JUNIO 2026. | AH31: 981.00 | AI31: 0.00 | AJ31: 156.96 | AK31: 0.00 | AL31: 1,137.96 | AM31: 20101021501 | AN31: 12101030000 | AO31: 20101021500
A32: PETROPLAZAS | B32: Fatima | C32: GISELA AGGLAE MARQUEZ VILLEGAS | D32: 7659F | E32: 02/06/2026 | F32: 03/06/2026 | G32: 03/06/2026 | H32: 5612.5 | I32: Pesos (MXN) | J32: 1 | K32: 5612.5 | L32: BLACKVIEW BV5500 PLUS | N32: 4838.36 | R32: ALMACEN | S32: Equipo de Computo | T32: Accesorios Comunicaciones | U32: E000000121 | V32: 73163 | W32: 66140 | X32: 60268 | Y32: OPERACIONES GASOLINERAS | Z32: Diego Alejandro Estrada Ramos | AA32: ES_Fatima | AB32: Zona de despacho | AE32: PAGADA | AF32: Zona de despacho | AG32: FAVOR DE ENTREGAR EN CEDIS MAZATLAN CON ISABEL. EQUIPO CUBOT KINGKONG PARA ESTACION FATIMA. | AH32: 4,838.36 | AI32: 0.00 | AJ32: 774.14 | AK32: 0.00 | AL32: 5,612.50 | AM32: 20101021501 | AN32: 12101030000 | AO32: 20101021500
A33: PETROPLAZAS | B33: CERRITOS | C33: Jose Carmen Montaño Aramburo | D33: A62F830168 | E33: 01/06/2026 | F33: 03/06/2026 | G33: 03/06/2026 | H33: 1738.84 | I33: Pesos (MXN) | J33: 1 | K33: 1738.84 | L33: Abanico | N33: 1499 | R33: ALMACEN | S33: Equipo de Transporte | T33: Sistema de Enfriamiento | U33: E000000197 | V33: 73145 | W33: 66214 | X33: 60158 | Y33: OPERACIONES | Z33: Maria Isabel Vega Gaxiola | AA33: ES_Cerritos | AB33: A. BAÑOS AL PUBLICO | AE33: PAGADA | AF33: A. BAÑOS AL PUBLICO | AG33: COMPRA POR VENTILADOR MYTEK DE PARED 20” SOLICITADO PARA ESTACION CERRITOS Nota: Facturar a inicios de junio y Uso de cfdi gastos en general. ENTREGAR EN CEDIS MAZATLAN CON ISABEL VEGA. | AH33: 1,499.00 | AI33: 0.00 | AJ33: 239.84 | AK33: 0.00 | AL33: 1,738.84 | AM33: 20101021501 | AN33: 12101030000 | AO33: 20101021500
A34: PETROPLAZAS | B34: AEROPUERTO | C34: JOHAN AGUILAR VIZCARRA | D34: A16653 | E34: 01/06/2026 | F34: 03/06/2026 | G34: 03/06/2026 | H34: 16646 | I34: Pesos (MXN) | J34: 1 | K34: 16646 | L34: BLUE HD ANTICONTAMINANTE PARA MOTOR DIESEL | N34: 287 | R34: ALMACEN | S34: Aceite y Lubricantes | T34: Aceite | U34: E000000284 | V34: 73360 | W34: 66511 | X34: 60350 | Y34: OPERACIONES | Z34: Maria Isabel Vega Gaxiola | AA34: ES_Aeropuerto | AB34: ESTACION AEROPUERTO | AE34: PAGADA | AF34: ESTACION AEROPUERTO | AG34: PAGO A FACT. A 16653 POR 50 KIT DE UREAS SOLICITADOS PAR PUNTO DE VENTA ESTACION AEROPUERTO, JUNIO 2026. PROGRAMAR A PAGO EL 04/06/2026 | AH34: 14,350.00 | AI34: 0.00 | AJ34: 2,296.00 | AK34: 0.00 | AL34: 16,646.00 | AM34: 20101021501 | AN34: 12101030000 | AO34: 20101021500
A35: PETROPLAZAS | B35: MUNICH II | C35: GISELA AGGLAE MARQUEZ VILLEGAS | D35: 62932 | E35: 02/06/2026 | F35: 03/06/2026 | G35: 03/06/2026 | H35: 5612.5 | I35: Pesos (MXN) | J35: 1 | K35: 5612.5 | L35: BLACKVIEW BV5500 PLUS | N35: 4838.36 | R35: ALMACEN | S35: Equipo de Computo | T35: Accesorios Comunicaciones | U35: E000000175 | V35: 73148 | W35: 66248 | X35: 60251 | Y35: OPERACIONES GASOLINERAS | Z35: Maria Isabel Vega Gaxiola | AA35: ES_MunichII | AB35: A. ZONA DE DESPACHO | AE35: PAGADA | AF35: A. ZONA DE DESPACHO | AG35: FAVOR DE ENTREGAR EN CEDIS MAZATLAN CON ISABEL. EQUIPO CUBOT KINGKONG ES 3 PARA ESTACION MUNICH II. | AH35: 4,838.36 | AI35: 0.00 | AJ35: 774.14 | AK35: 0.00 | AL35: 5,612.50 | AM35: 20101021501 | AN35: 12101030000 | AO35: 20101021500
A36: PETROPLAZAS | B36: Sabalo | C36: Kuroda Plomeria y Azulejos SA de CV | D36: FIA177489 | E36: 01/06/2026 | F36: 03/06/2026 | G36: 03/06/2026 | H36: 1099 | I36: Pesos (MXN) | J36: 1 | K36: 1099 | L36: TAZA DE BAÑO WC CON TANQUE | N36: 947.41 | R36: ALMACEN | S36: Gastos diversos | T36: Varios (Gastos Diversos) | U36: E000000204 | V36: 73286 | W36: 65500 | X36: 60233 | Y36: OPERACIONES GASOLINERAS | Z36: Maria Isabel Vega Gaxiola | AA36: ES_Sabalo | AB36: CC OPERACIONES | AC36: 0 | AE36: PAGADA | AF36: CC OPERACIONES | AG36: COMPRA POR WC BLANCO AHORRADOR REDONDO MODELO ECO ACUACER SOLICITADO PARA ESTACION SABALO, JUNIO 2026. ENTREGAR EN CEDIS MAZATLAN (almacen flores magon) CON ISABEL VEGA. | AH36: 947.41 | AI36: 0.00 | AJ36: 151.59 | AK36: 0.00 | AL36: 1,099.00 | AM36: 20101021501 | AN36: 12101030000 | AO36: 20101021500
A37: PETROPLAZAS | B37: Sabalo | C37: Jose Carmen Montaño Aramburo | D37: B5E1530167 | E37: 01/06/2026 | F37: 03/06/2026 | G37: 03/06/2026 | H37: 3477.68 | I37: Pesos (MXN) | J37: 1 | K37: 3477.68 | L37: Abanico | N37: 1499 | R37: ALMACEN | S37: Equipo de Transporte | T37: Sistema de Enfriamiento | U37: E000000203 | V37: 73142 | X37: 60249 | Z37: Maria Isabel Vega Gaxiola | AE37: PAGADA | AF37: Estatus Surtido | AG37: COMPRA POR 2 VENTILADORES MYTEK DE PARED 20” SOLICITADOS PARA ESTACION SABALO, Nota, facturar a inicios de junio y uso de cfdi gastos en general. ENTREGAR EN CEDIS MAZATLAN CON ISABEL VEGA. | AH37: 2,998.00 | AI37: 0.00 | AJ37: 479.68 | AK37: 0.00 | AL37: 3,477.68 | AM37: 20101021501 | AN37: 12101030000 | AO37: 20101021500
A38: PETROPLAZAS | B38: URBIVILLA | C38: JORGE LUIS LIZARRAGA GARATE | D38: BCR674 | E38: 01/06/2026 | F38: 04/06/2026 | G38: 04/06/2026 | H38: 721.87 | I38: Pesos (MXN) | J38: 1 | K38: 721.87 | L38: BOLSA NEGRA JUMBO | N38: 35.84 | R38: ALMACEN | S38: Artículos de Limpieza | T38: Artículos de Limpieza | U38: E000000083 | V38: 73264 | W38: 66215 | X38: 60177 | Y38: OPERACIONES GASOLINERAS | Z38: Maria Isabel Vega Gaxiola | AA38: URBIVILLA | AB38: ESTACION URBIVILLA | AE38: PAGADA | AF38: ESTACION URBIVILLA | AG38: FAVOR DE ENTREGAR EN ESTACION URBIVILLA CON EL SUPERVISOR. MATERIAL DE LIMPIEZA DEL MES DE JUNIO 2026. AROMATIZANTE BRISA DE MAR | AH38: 629.08 | AI38: 0.00 | AJ38: 100.65 | AK38: 0.00 | AL38: 721.87 | AM38: 20101021501 | AN38: 12101030000 | AO38: 22201020000 | AP38: 20101021500
A39: PETROPLAZAS | B39: 12 de Mayo | C39: Operadora Polar SA de CV | D39: MZF445030 | E39: 01/06/2026 | F39: 04/06/2026 | G39: 04/06/2026 | H39: 1995.43 | I39: Pesos (MXN) | J39: 1 | K39: 1995.43 | L39: PASTILLA AROMATIZANTE PARA BAÑO | N39: 10.8 | R39: ALMACEN | S39: Artículos de Limpieza | T39: Artículos de Limpieza | U39: E000000168 | V39: 73257 | W39: 66301 | X39: 60151 | Y39: OPERACIONES | Z39: Maria Isabel Vega Gaxiola | AA39: ES_12 de Mayo | AB39: BAÑOS ESTACION | AE39: PAGADA | AF39: BAÑOS ESTACION | AG39: FAVOR DE ENTREGAR EN ESTACION 12 DE MAYO CON EL SUPERVISOR. MATERIAL DE LIMPIEZA DEL MES DE JUNIO 2026. | AH39: 1,720.20 | AI39: 0.00 | AJ39: 275.23 | AK39: 0.00 | AL39: 1,995.43 | AM39: 20101021501 | AN39: 12101030000 | AO39: 20101021500
A40: PETROPLAZAS | B40: URBIVILLA | C40: Operadora Polar SA de CV | D40: MZF445026 | E40: 01/06/2026 | F40: 04/06/2026 | G40: 04/06/2026 | H40: 1004.79 | I40: Pesos (MXN) | J40: 1 | K40: 1004.79 | L40: PAPEL HIGIENICO JUMBO BLANCO | N40: 26.4333 | R40: ALMACEN | S40: Artículos de Limpieza | T40: Artículos de Limpieza | U40: E000000082 | V40: 73263 | W40: 66215 | X40: 60177 | Y40: OPERACIONES GASOLINERAS | Z40: Maria Isabel Vega Gaxiola | AA40: URBIVILLA | AB40: ESTACION URBIVILLA | AE40: PAGADA | AF40: ESTACION URBIVILLA | AG40: FAVOR DE ENTREGAR EN ESTACION URBIVILLA CON EL SUPERVISOR. MATERIAL DE LIMPIEZA DEL MES DE JUNIO 2026. | AH40: 866.20 | AI40: 0.00 | AJ40: 138.59 | AK40: 0.00 | AL40: 1,004.79 | AM40: 20101021501 | AN40: 12101030000 | AO40: 20101021500
...

Sheet Resumen
A1: RESUMEN DE COMPARACIÓN SUCURSALES
A2: Generado: 23/06/2026 14:14:48
A4: Resultado | B4: Cantidad | C4: Porcentaje | D4: Descripción
A5: MATCH ✓ | B5: 314 | C5: 68.1% | D5: 1 sucursal detectada y coincide con Grupo CC
A6: MISMATCH ✗ | B6: 11 | C6: 2.4% | D6: 1 sucursal detectada pero NO coincide con Grupo CC
A7: DISTRIBUCIÓN | B7: 115 | C7: 24.9% | D7: 2+ sucursales detectadas — el total debe distribuirse entre ellas
A8: Sin sucursal | B8: 21 | C8: 4.6% | D8: No se detectó ninguna sucursal en las observaciones
A9: TOTAL | B9: 461 | C9: 100.0% | D9: Total de registros procesados

Sheet Resumen CuentasC
A1: RESUMEN DE CONCILIACIÓN CUENTAS CONTABLES
A2: Generado: 23/06/2026 14:14:48
A4: Resultado | B4: Cantidad | C4: Porcentaje | D4: Descripción
A5: Match ✓ | B5: 1517 | C5: 329.1% | D5: Cuenta contable de SIPP encontrada en el catálogo (gastos o proveedores)
A6: Mismatch ✗ | B6: 5 | C6: 1.1% | D6: SIPP devolvió una cuenta contable pero no existe en el catálogo
A7: Cuadre | B7: 3 | C7: 0.7% | D7: Cuenta de cuadre contable (_CUA-DRE-- u otra con letras) — no se busca en catálogo
A8: Sin dato SIPP | B8: 5 | C8: 1.1% | D8: SIPP no devolvió ninguna cuenta contable para esta factura
A9: TOTAL | B9: 461 | C9: 100.0% | D9: Total de registros procesados

Sheet Por Sucursal
A1: Sucursal | B1: MATCH ✓ | C1: MISMATCH ✗ | D1: DISTRIBUCIÓN | E1: Total
A2: 12 DE MAYO | B2: 5 | C2: 0 | D2: 2 | E2: 7
A3: AEROPUERTO | B3: 14 | C3: 0 | D3: 3 | E3: 17
A4: ALHUEY 1 | B4: 7 | C4: 0 | D4: 4 | E4: 11
A5: ALHUEY 2 | B5: 6 | C5: 1 | D5: 3 | E5: 10
A6: AU-144 | B6: 0 | C6: 0 | D6: 1 | E6: 1
A7: AU-151 | B7: 0 | C7: 0 | D7: 1 | E7: 1
A8: AU-152 | B8: 0 | C8: 0 | D8: 1 | E8: 1
A9: BELLAVISTA | B9: 7 | C9: 0 | D9: 1 | E9: 8
A10: CARDONES | B10: 10 | C10: 0 | D10: 2 | E10: 12
A11: CARRASCO | B11: 8 | C11: 0 | D11: 3 | E11: 11
A12: CERRITOS | B12: 8 | C12: 0 | D12: 3 | E12: 11
A13: COLOSIO | B13: 4 | C13: 0 | D13: 2 | E13: 6
... A59: ZONA NORTE | B59: 0 | C59: 0 | D59: 4 | E59: 4

Sheet Comparación
A1: Sucursal | B1: Factura | C1: Folio | D1: Grupo Centro de Costo | E1: CC OC | F1: Observaciones OC | G1: Sucursales Detectadas | H1: Resultado | J1: ESTACION QUE DEBE CARGARSE
A2: Alamos | B2: A4860 | C2: SRV0000068 | D2: ES_Alamos | E2: AUTOMOVIL - AU-151 | F2: Movimiento generado en automático por sistema. Proceso de Carga Masiva de Facturas | G2: AU-151 | H2: DISTRIBUCIÓN (UT)
A3: Petroplazas Corporativo | B3: 64F6E70 | C3: SRV0005503 | D3: ES_Corporativo | E3: CC ADMINISTRACION | F3: PROYECTO DE CONSTRUCCION DE ESTACION COLON. CFDI I01 CONSTRUCCION | G3: ES_Corporativo | H3: DISTRIBUCIÓN (Corp)
A4: Rosario | B4: FA23246 | C4: E000000121 | E4: Estatus Surtido | F4: COMPRA POR MATERIAL PARA STOK APOYOA DISPENSARIOS ESTACION ROSARIO, MAYO 2026. Nota; Facturar a inicios de junio por favor. ENTREGAR EN CEDIS MAZATLAN CON ISABLE VEGA. | G4: ROSARIO | H4: MATCH ✓
A5: Fatima | B5: A4861 | C5: SRV0000040 | D5: ES_Fatima | E5: AUTOMOVIL AU-131 | F5: Movimiento generado en automático por sistema. Proceso de Carga Masiva de Facturas | H5: Sin sucursal | J5: FATIMA
A6: Escuinapa | B6: FA23247 | C6: E000000182 | E6: Estatus Surtido | F6: COMPRA POR PISTOLA PARA DESP. GASOL. NEGRA DE 3/4" 11-B OPW SOLICTADAS PARA ESTACION ESCUINAPA, MAYO 2026. Nota, Facturar a inicios de junio ENTREGAR EN CEDIS MAZATLAN CON ISABEL VEGA. | G6: ESCUINAPA | H6: MATCH ✓
A7: AEROPUERTO | B7: M00646230 | C7: E000000282 | D7: ES_Aeropuerto | E7: ESTACION AEROPUERTO | F7: COMPRA POR 6 TUBO LED 36W T8 Y Y 10 TUBO LED 18W T8 120cm SOLICITADOS PARA ESTACION AEROPUERTO, JUNIO 2026. ENTREGAR EN CEDIS MAZATLAN CON ISABEL VEGA. | G7: AEROPUERTO | H7: MATCH ✓
A8: La Colorada | B8: MAZ4892 | C8: E000000183 | D8: ES_LA_COLORADA | E8: OFICINAS ADMINISTRATIVAS. | F8: FAVOR DE ENTREGAR EN ESTACION LA COLORADA CON EL SUPERVISOR AL DOMICILIO CALLE LATERAL CARRETERA SN, COL. NUEVO HERMOSILLO, HERMOSILLO, SONORA, CP. 83296. MATERIAL DE LIMPIEZA DEL MES DE JUNIO 2026. | G8: LA COLORADA | H8: MATCH ✓
A9: Fatima | B9: A6054 | C9: E000000119 | D9: ES_Fatima | E9: Estacion Fatima | F9: CORRESPONDE A LA FACTURA A6054. CAMARA DE SEGURIDAD Y ADITAMIENTO EN ESTACION FATIMA. | G9: FATIMA | H9: MATCH ✓
A10: Petroplazas Corporativo | B10: F701219 | C10: SRV0005507 | D10: ES_Corporativo | E10: GASTOS GENERALES | F10: PAGO DE LA FACT. 19 POR EL ARRENDAMIENTO DE TERRENO DE ESTACION EL DIEZ, (LA O.C. SE HIZO POR 12 MESES, LOS CUALES SE IRAN PAGANDO MES A MES). PROGRAMAR A PAGO PARA EL 04/06/2026. | G10: EL DIEZ | H10: MISMATCH ✗ | J10: EL DIEZ
A11: CEDIS Mazatlán | B11: 462FC | C11: SRV0000604 | D11: EST_EL_CONCHI | E11: Escuinapa | F11: SERVICIO RED JOSHUA SITIO MAZATLAN, JUNIO 2026 | H11: Sin sucursal | J11: MAZATLAN GENERAL Y SUR
A12: Petroplazas Corporativo | B12: I40 | C12: SRV0005504 | D12: ES_Corporativo | E12: CC ADMINISTRACION | F12: CORRESPONDE A LA FACTURA 40. SERVICIO DE MANTENIMIENTO Y DESARROLLO DE SOFTWARE DE CORPORATIVO DIVISION GASOLINERAS. | G12: ES_Corporativo | H12: DISTRIBUCIÓN (Corp)
A13: CEDIS Culiacán | B13: E018C998 | C13: E000000270 | E13: Estatus Surtido | F13: FAVOR DE ENTREGAR EN CEDIS CULIACAN CON DIEGO. PANTALON DESPACHADOR AZUL PARA STOCK DE ZONA CLN, ANGOSTURA Y NORTE. | G13: ZONA CLN | H13: DISTRIBUCIÓN (1)
A14: CEDIS Culiacán | B14: B0C2F997 | C14: E000000271 | E14: Estatus Surtido | F14: FAVOR DE ENTREGAR EN CEDIS CULIACAN CON DIEGO. PANTALON DESPACHADOR AZUL PARA STOCK DE ZONA CLN, ANGOSTURA Y NORTE. | G14: ZONA CLN | H14: DISTRIBUCIÓN (1)
A15: Revolucion | B15: A1549 | C15: E000000153 | D15: ES_Revolucion | E15: Baños publicos | F15: FAVOR DE ENTREGAR EN ESTACION REVOLUCION CON EL SUPERVISOR AL DOMICILIO BLVD. LUIS DONAL. COLOSIO NO. 615, COL. REVOLUCION MEXICANA, GUASAVE, SINALOA, C.P. 81016. MATERIAL DE LIMPIEZA DEL MES DE JUNIO 2026. | G15: REVOLUCION / COLOSIO | H15: DISTRIBUCIÓN (2)
A16: CEDIS Culiacán | B16: CCCEC | C16: SRV0000460 | D16: PERICOS | E16: CUAUHTEMOC | F16: SERVICIO RED JOSHUA SITIO CULIACAN, JUNIO 2026 | H16: Sin sucursal | J16: CUAHUTEMOC, PARQUES, PERICOS Y PERICOS CENTRO
A17: La Colorada | B17: GHMO004237 | C17: SRV0000194 | D17: ES_LA_COLORADA | E17: ESTACION LA COLORADA | F17: CORRESPONDE A LA FACTURA GHMO004237. SERVICIO DE GAS LP PARA AREA DE PENSION DE ESTACION LA COLORADA. | G17: LA COLORADA | H17: MATCH ✓
A18: Forjadores | B18: 72C4F | C18: SRV0000296 | D18: ES_FORJADORES | E18: D. ADMINISTRACION | F18: SERVICIO RED JOSHUA SITIO PAZ, JUNIO 2026 | H18: Sin sucursal | J18: LA PAZ
A19: SANTA ROSA | B19: MZF445034 | C19: E000000138 | D19: ES_SANTA_ROSA | E19: BAÑOS AL PÚBLICO | F19: FAVOR DE ENTREGAR EN ESTACION SANTA ROSA CON EL SUPERVISOR. MATERIAL DE LIMPIEZA DEL MES DE JUNIO 2026. | G19: SANTA ROSA | H19: MATCH ✓
A20: CEDIS Mazatlán | B20: 20251611 | C20: E000000461 | E20: Estatus Surtido | F20: FAVOR DE ENTREGAR EN CEDIS MAZATLAN CON ISABEL. PANTALON DE VESTIR CABALLERO AZUL MARINO PARA STOCK DE CEDIS MAZATLAN. | H20: Sin sucursal | J20: MAZATLAN GENERAL
A21: CEDIS Mazatlán | B21: F68961 | C21: E000000462 | E21: Estatus Surtido | F21: FAVOR DE ENTREGAR EN CEDIS MAZATLAN CON ISABEL AL DOMICILIO AZALEA NO. 4901, COL. RICARDO FLORES MAGON, C.P. 82190, MAZATLAN, SINALOA. GORRA ACRILANA AMARILLO / REY C/BORDADO FTE REDPETROIL PARA STOCK DE CEDIS MAZATLAN PARA ESTACIONES SABALO, AEROPUERTO, CONCORDIA, HABAL, 12 DE MAYO, FORESTA, URBIVILLA, GRIJALVA, ROSARIO Y ESCUINAPA. | G21: 12 DE MAYO / AEROPUERTO / ESCUINAPA / CONCORDIA / URBIVILLA / GRIJALVA / FORESTA / ROSARIO / SABALO / HABAL | H21: DISTRIBUCIÓN (10)
A22: SANTA ROSA | B22: BCR672 | C22: E000000139 | D22: ES_SANTA_ROSA | E22: BAÑOS AL PÚBLICO | F22: FAVOR DE ENTREGAR EN ESTACION SANTA ROSA CON EL SUPERVISOR. MATERIAL DE LIMPIEZA DEL MES DE JUNIO 2026. | G22: SANTA ROSA | H22: MATCH ✓
A23: Alamos | B23: FDF0430176 | C23: E000000128 | D23: CC Empleados | E23: CC Jose Carlos Valdez Nuñez | F23: FAVOR DE ENTREGAR EN CEDIS MAZATLAN CON ISABEL. CARGADOR LENOVO ADL45WCC PARA LAPTOP LENOVO IDEAPAD 320 DE ING. JOSE CARLOS JEFE DE PISO ZONA NORTE. | G23: ZONA NORTE | H23: DISTRIBUCIÓN (1)
A24: Sabalo | B24: M00646285 | C24: E000000207 | D24: ES_Sabalo | E24: CC OPERACIONES | F24: CORRESPONDE A LA FACTURA M-00646285. MATERIAL ELECTRICO PARA ESTACION SABALO. | G24: SABALO | H24: MATCH ✓
A25: SANTA ROSA | B25: MZF445096 | C25: E000000141 | D25: ES_SANTA_ROSA | E25: CC OPERACIONES | F25: CORRESPONDE A LA FACTURA MZF445096. EMPLAYE PARA ESTACION SANTA ROSA. | G25: SANTA ROSA | H25: MATCH ✓
A26: La Foresta | B26: MZF445025 | C26: E000000180 | D26: ES_La Foresta | E26: CC OPERACIONES | F26: FAVOR DE ENTREGAR EN ESTACION FORESTA CON EL SUPERVISOR. MATERIAL DE LIMPIEZA DEL MES DE JUNIO 2026. | G26: FORESTA | H26: MATCH ✓
A27: Fatima | B27: A1551 | C27: E000000123 | D27: ES_Fatima | E27: Baños publicos | F27: FAVOR DE ENTREGAR EN ESTACION FATIMA CON EL SUPERVISOR AL DOMICILIO ANGEL FLORES NTE. 983 COL. CENTRO, AHOME LOS MOCHIS, SINALOA, C.P. 81200. MATERIAL DE LIMPIEZA DEL MES DE JUNIO 2026. | G27: FATIMA | H27: MATCH ✓
A28: Alamos | B28: A1550 | C28: E000000130 | D28: ES_Alamos | E28: Baños publicos | F28: FAVOR DE ENTREGAR EN ESTACION ALAMOS CON EL SUPERVISOR AL DOMICILIO BLVD. MACARIO GAXIOLA NO. 1500 SUR, FRACC. LOS ALAMOS 1, AHOME LOS MOCHIS, SINALOA, C.P. 81280. MATERIAL DE LIMPIEZA DEL MES DE JUNIO 2026. | G28: LOS ALAMOS | H28: MATCH ✓
A29: Petroplazas Corporativo | B29: 2C6A1 | C29: SRV0005508 | D29: ES_Corporativo | E29: CC Administracion | F29: SERVICIO RED JOSHUA SITIO NAS, JUNIO 2026 | G29: ES_Corporativo | H29: DISTRIBUCIÓN (Corp)
A30: ALHUEY1 | B30: FC26295 | C30: E000000195 | D30: ES_ALHUEY1 | E30: Estacion Alhuey 1 | F30: COMPRA DE 3 PATITAS (FUSIBLE) PARA VALVULA SHUT OFF PARA ESTACION ALHUEY 1. (ENTREGAR EN ALMACEN DE REFACCIONES DE CAMPO EL DIEZ). Y FACTURAR CON 1 DE JUNIO. | G30: ALHUEY 1 / EL DIEZ | H30: DISTRIBUCIÓN (2)
A31: Dos Valles | B31: A1548 | C31: E000000131 | D31: ES_Dos Valles | E31: Baños publicos | F31: FAVOR DE ENTREGAR EN ESTACION DOS VALLE CON EL SUPERVISOR AL DOMICILIO BLVD. LUIS DONALDO COLOSIO NO. 264, COL. OCORO, GUASAVE, SINALOA, C.P. 81010. MATERIAL DE LIMPIEZA DEL MES DE JUNIO 2026. | G31: DOS VALLES / COLOSIO | H31: DISTRIBUCIÓN (2)
A32: Fatima | B32: 7659F | C32: E000000121 | D32: ES_Fatima | E32: Zona de despacho | F32: FAVOR DE ENTREGAR EN CEDIS MAZATLAN CON ISABEL. EQUIPO CUBOT KINGKONG PARA ESTACION FATIMA. | G32: FATIMA | H32: MATCH ✓
A33: CERRITOS | B33: A62F830168 | C33: E000000197 | D33: ES_Cerritos | E33: A. BAÑOS AL PUBLICO | F33: COMPRA POR VENTILADOR MYTEK DE PARED 20” SOLICITADO PARA ESTACION CERRITOS Nota: Facturar a inicios de junio y Uso de cfdi gastos en general. ENTREGAR EN CEDIS MAZATLAN CON ISABEL VEGA. | G33: CERRITOS | H33: MATCH ✓
... A36: Sabalo | B36: FIA177489 | C36: E000000204 | D36: ES_Sabalo | E36: CC OPERACIONES | F36: COMPRA POR WC BLANCO AHORRADOR REDONDO MODELO ECO ACUACER SOLICITADO PARA ESTACION SABALO, JUNIO 2026. ENTREGAR EN CEDIS MAZATLAN (almacen flores magon) CON ISABEL VEGA. | G36: FLORES MAGON / SABALO | H36: DISTRIBUCIÓN (2)
A37: Sabalo | B37: B5E1530167 | C37: E000000203 | E37: Estatus Surtido | F37: COMPRA POR 2 VENTILADORES MYTEK DE PARED 20” SOLICITADOS PARA ESTACION SABALO, Nota, facturar a inicios de junio y uso de cfdi gastos en general. ENTREGAR EN CEDIS MAZATLAN CON ISABEL VEGA. | G37: SABALO | H37: MATCH ✓
A38: URBIVILLA | B38: BCR674 | C38: E000000083 | D38: URBIVILLA | E38: ESTACION URBIVILLA | F38: FAVOR DE ENTREGAR EN ESTACION URBIVILLA CON EL SUPERVISOR. MATERIAL DE LIMPIEZA DEL MES DE JUNIO 2026. AROMATIZANTE BRISA DE MAR | G38: URBIVILLA | H38: MATCH ✓
A39: 12 de Mayo | B39: MZF445030 | C39: E000000168 | D39: ES_12 de Mayo | E39: BAÑOS ESTACION | F39: FAVOR DE ENTREGAR EN ESTACION 12 DE MAYO CON EL SUPERVISOR. MATERIAL DE LIMPIEZA DEL MES DE JUNIO 2026. | G39: 12 DE MAYO | H39: MATCH ✓
A40: URBIVILLA | B40: MZF445026 | C40: E000000082 | D40: URBIVILLA | E40: ESTACION URBIVILLA | F40: FAVOR DE ENTREGAR EN ESTACION URBIVILLA CON EL SUPERVISOR. MATERIAL DE LIMPIEZA DEL MES DE JUNIO 2026. | G40: URBIVILLA | H40: MATCH ✓
A41: Flores Magon | B41: MZF445027 | C41: E000000436 | D41: ES_Flores Magon | E41: BAÑOS ESTACION | F41: FAVOR DE ENTREGAR EN ESTACION FLORES MAGON CON EL SUPERVISOR. MATERIAL DE LIMPIEZA DEL MES DE JUNIO 2026. | G41: FLORES MAGON | H41: MATCH ✓
A42: GRIJALVA | B42: MZF445032 | C42: E000000156 | D42: GRIJALVA | E42: ESTACION GRIJAVA | F42: FAVOR DE ENTREGAR EN ESTACION GRIJALVA CON EL SUPERVISOR. MATERIAL DE LIMPIEZA DEL MES DE JUNIO 2026. | G42: GRIJALVA | H42: MATCH ✓
...

Sheet Distribución
A1: Sucursal | B1: Factura | C1: Folio | D1: Grupo CC | E1: CC OC | F1: Observaciones OC | G1: Sucursales Detectadas | H1: # Estaciones
A2: Alamos | B2: A4860 | C2: SRV0000068 | D2: ES_Alamos | E2: AUTOMOVIL - AU-151 | F2: Movimiento generado en automático por sistema. Proceso de Carga Masiva de Facturas | G2: AU-151 | H2: 0
A3: Petroplazas Corporativo | B3: 64F6E70 | C3: SRV0005503 | D3: ES_Corporativo | E3: CC ADMINISTRACION | F3: PROYECTO DE CONSTRUCCION DE ESTACION COLON. CFDI I01 CONSTRUCCION | G3: ES_Corporativo | H3: 0
A4: Petroplazas Corporativo | B4: I40 | C4: SRV0005504 | D4: ES_Corporativo | E4: CC ADMINISTRACION | F4: CORRESPONDE A LA FACTURA 40. SERVICIO DE MANTENIMIENTO Y DESARROLLO DE SOFTWARE DE CORPORATIVO DIVISION GASOLINERAS. | G4: ES_Corporativo | H4: 0
A5: CEDIS Culiacán | B5: E018C998 | C5: E000000270 | E5: Estatus Surtido | F5: FAVOR DE ENTREGAR EN CEDIS CULIACAN CON DIEGO. PANTALON DESPACHADOR AZUL PARA STOCK DE ZONA CLN, ANGOSTURA Y NORTE. | G5: ZONA CLN | H5: 0
A6: CEDIS Culiacán | B6: B0C2F997 | C6: E000000271 | E6: Estatus Surtido | F6: FAVOR DE ENTREGAR EN CEDIS CULIACAN CON DIEGO. PANTALON DESPACHADOR AZUL PARA STOCK DE ZONA CLN, ANGOSTURA Y NORTE. | G6: ZONA CLN | H6: 0
A7: Revolucion | B7: A1549 | C7: E000000153 | D7: ES_Revolucion | E7: Baños publicos | F7: FAVOR DE ENTREGAR EN ESTACION REVOLUCION CON EL SUPERVISOR AL DOMICILIO BLVD. LUIS DONAL. COLOSIO NO. 615, COL. REVOLUCION MEXICANA, GUASAVE, SINALOA, C.P. 81016. MATERIAL DE LIMPIEZA DEL MES DE JUNIO 2026. | G7: REVOLUCION / COLOSIO | H7: 2
A8: CEDIS Mazatlán | B8: F68961 | C8: E000000462 | E8: Estatus Surtido | F8: FAVOR DE ENTREGAR EN CEDIS MAZATLAN CON ISABEL AL DOMICILIO AZALEA NO. 4901, COL. RICARDO FLORES MAGON, C.P. 82190, MAZATLAN, SINALOA. GORRA ACRILANA AMARILLO / REY C/BORDADO FTE REDPETROIL PARA STOCK DE CEDIS MAZATLAN PARA ESTACIONES SABALO, AEROPUERTO, CONCORDIA, HABAL, 12 DE MAYO, FORESTA, URBIVILLA, GRIJALVA, ROSARIO Y ESCUINAPA. | G8: 12 DE MAYO / AEROPUERTO / ESCUINAPA / CONCORDIA / URBIVILLA / GRIJALVA / FORESTA / ROSARIO / SABALO / HABAL | H8: 10
A9: Alamos | B9: FDF0430176 | C9: E000000128 | D9: CC Empleados | E9: CC Jose Carlos Valdez Nuñez | F9: FAVOR DE ENTREGAR EN CEDIS MAZATLAN CON ISABEL. CARGADOR LENOVO ADL45WCC PARA LAPTOP LENOVO IDEAPAD 320 DE ING. JOSE CARLOS JEFE DE PISO ZONA NORTE. | G9: ZONA NORTE | H9: 0
A10: Petroplazas Corporativo | B10: 2C6A1 | C10: SRV0005508 | D10: ES_Corporativo | E10: CC Administracion | F10: SERVICIO RED JOSHUA SITIO NAS, JUNIO 2026 | G10: ES_Corporativo | H10: 0
A11: ALHUEY1 | B11: FC26295 | C11: E000000195 | D11: ES_ALHUEY1 | E11: Estacion Alhuey 1 | F11: COMPRA DE 3 PATITAS (FUSIBLE) PARA VALVULA SHUT OFF PARA ESTACION ALHUEY 1. (ENTREGAR EN ALMACEN DE REFACCIONES DE CAMPO EL DIEZ). Y FACTURAR CON 1 DE JUNIO. | G11: ALHUEY 1 / EL DIEZ | H11: 2
A12: Dos Valles | B12: A1548 | C12: E000000131 | D12: ES_Dos Valles | E12: Baños publicos | F12: FAVOR DE ENTREGAR EN ESTACION DOS VALLE CON EL SUPERVISOR AL DOMICILIO BLVD. LUIS DONALDO COLOSIO NO. 264, COL. OCORO, GUASAVE, SINALOA, C.P. 81010. MATERIAL DE LIMPIEZA DEL MES DE JUNIO 2026. | G12: DOS VALLES / COLOSIO | H12: 2
A13: Sabalo | B13: FIA177489 | C13: E000000204 | D13: ES_Sabalo | E13: CC OPERACIONES | F13: COMPRA POR WC BLANCO AHORRADOR REDONDO MODELO ECO ACUACER SOLICITADO PARA ESTACION SABALO, JUNIO 2026. ENTREGAR EN CEDIS MAZATLAN (almacen flores magon) CON ISABEL VEGA. | G13: FLORES MAGON / SABALO | H13: 2
A14: Bellavista | B14: AA10863 | C14: E000000094 | D14: ES_Bellavista | E14: Estacion BellaVista | F14: COMPRA DE PINTURA PARA EL MTTO. DE LAS REJILLAS DE TRAMPAS DE LA ESTACION BELLAVISTA. (ENTREGAR EN LA ESTACION EL PAPALOTE, CON UN PAPEL QUE DIGA QUE ES DE BELLAVISTA). | G14: BELLAVISTA / PAPALOTE | H14: 2
A15: Petroplazas Corporativo | B15: B4765 | C15: SRV0005509 | D15: ES_Corporativo | E15: GASTOS GENERALES | F15: SERVICIO DE IMPRESION DE ETIQUETAS MAGNA Y PREMIUM PARA ESTACION SANTA MONICA. | G15: ES_Corporativo | H15: 0
A16: CEDIS Mazatlán | B16: A851A3268 | C16: SRV0000605 | D16: Concordia | E16: Aeropuerto 1 | F16: PAGO A FACT. 3268 POR SERVICIO DE CONSULTORIA Y ELABORACION DOCUMENTAL EN MATERIA DE LA STPS ESTACION HABAL, CARDONES, AEROPUERTO Y CONCORDIA, JUNIO 2026. PROGRAMAR A PAGO EL 11/06/2026 | G16: AEROPUERTO / CONCORDIA / CARDONES / HABAL | H16: 4
A17: CEDIS Culiacán | B17: AA43839 | C17: SRV0000461 | D17: CUAUHTEMOC | E17: REVOLUCION | F17: CORRESPONDE A LA FACTURA AA43839. SERVICIO DE IMPRESION DE CUPONERAS CITICINEMAS DE JUNIO 2026 DE ESTACION DOS VALLE, REVOLUCION Y CUAUHTEMOC. | G17: REVOLUCION / CUAUHTEMOC / DOS VALLES | H17: 3
A18: CEDIS Mazatlán | B18: 02FF93270 | C18: SRV0000606 | D18: Colosio | E18: Foresta | F18: CORRESPONDE A LA FACTURA 3270. CONSULTORIA Y ELABORACION DOCUMENTAL DE LA STPS DEL MES DE JUNIO 2026 ZONA MZT 3. | G18: ZONA MZT 3 | H18: 0
A19: CEDIS Mazatlán | B19: BAE1E3271 | C19: SRV0000607 | D19: Grijalva | E19: Juan Carrasco | F19: CORRESPONDE A LA FACTURA 3271. CONSULTORIA Y ELABORACION DOCUMENTAL DE LA STPS DEL MES DE JUNIO 2026 ZONA MZT 4. | G19: ZONA MZT 4 | H19: 0
A20: ALHUEY2 | B20: TME357624 | C20: E000000131 | D20: ALHUEY 2 | E20: ESTACION | F20: COMPRA DE ROLLO TERMICO (80X70) PARA DISPENSARIOS DE LA ESTACION ALHUEY 2. ENTREGAR EN: AUTOPISTA CULIACAN-LOS MOCHIS KM. 110.5, ALHUEY, ANGOSTURA, SINALOA, C.P. 81610. | G20: ALHUEY 2 / ALHUEY 1 | H20: 2
... A39: Petroplazas Corporativo | B39: CDDC671 | C39: SRV0005531 | D39: ES_Corporativo | E39: CC ADMINISTRACION | F39: PROYECTO DE CONSTRUCCION DE ESTACION COLON. CFDI I01 CONSTRUCCION | G39: ES_Corporativo | H39: 0
A40: CEDIS Mazatlán | B40: FGC4202 | C40: E000000467 | E40: Estatus Surtido | F40: FAVOR DE ENTREGAR EN CEDIS MAZATLAN CON ISABEL AL DOMICILIO AZALEA NO. 4901, COL. RICARDO FLORES MAGON, C.P. 82190, MAZATLAN, SINALOA. UNIFORMES MARCA PEMEX PARA STOCK DE CEDIS PARA ESTACIONES PLAYAS, JUAN CARRASCO, HABAS. | G40: CARRASCO / PLAYAS / LAS HABAS | H40: 3
A41: CEDIS Mazatlán | B41: FGC4201 | C41: E000000466 | E41: Estatus Surtido | F41: FAVOR DE ENTREGAR EN CEDIS MAZATLAN CON ISABEL AL DOMICILIO AZALEA NO. 4901, COL. RICARDO FLORES MAGON, C.P. 82190, MAZATLAN, SINALOA. UNIFORMES MARCA PEMEX PARA STOCK DE CEDIS PARA ESTACIONES PLAYAS, JUAN CARRASCO, HABAS. | G41: CARRASCO / PLAYAS / LAS HABAS | H41: 3
A42: CEDIS Mazatlán | B42: K19476 | C42: SRV0000610 | D42: Sabalo | E42: Marina | F42: CORRESPONDE A LA FACTURA K19476. SERVICIO DE SERVIDOR VIRTUAL MENSUAL RESPALDOS EN LA NUBE Y SERVIDOR DE ACCESO A CLIENTES PARA FACTURACION JUNIO 2026 DE ESTACIONES DE ZONA MZT. | G42: ZONA MZT | H42: 0
A43: CEDIS Culiacán | B43: 866f81908 | C43: E000000276 | E43: Estatus Surtido | F43: FAVOR DE ENTREGAR EN CEDIS MAZATLAN CON ISABEL. PLAYERA POLO AZUL MARINO M/L LOGO (REDPETROIL Y GOTA) PARA CEDIS CULIACAN ESTACIONES ZONA CLN, ANGOSTURA Y NORTE. | G43: ZONA CLN | H43: 0
A44: CEDIS Mazatlán | B44: K19474 | C44: SRV0000609 | D44: Flores Magon | E44: Foresta | F44: CORRESPONDE A LA FACTURA K19474. SERVICIO DE SERVIDOR VIRTUAL MENSUAL RESPALDOS EN LA NUBE Y SERVIDOR DE ACCESO A CLIENTES PARA FACTURACION JUNIO 2026 DE ESTACIONES DE ZONA MZT 3. | G44: ZONA MZT 3 | H44: 0
A45: CEDIS Mazatlán | B45: 1e81f1907 | C45: E000000468 | E45: Estatus Surtido | F45: FAVOR DE ENTREGAR EN CEDIS MAZATLAN CON ISABEL. PLAYERA POLO AZUL MARINO M/L LOGO (REDPETROIL Y GOTA) PARA STOCK DE CEDIS PARA ESTACIONES SABALO, AEROPUERTO, CONCORDIA, HABAL, 12 DE MAYO, FORESTA, URBIVILLA, ROSARIO Y ESCUINAPA. | G45: 12 DE MAYO / AEROPUERTO / ESCUINAPA / CONCORDIA / URBIVILLA / FORESTA / ROSARIO / SABALO / HABAL | H45: 9
A46: CEDIS Culiacán | B46: K19475 | C46: SRV0000465 | D46: CUAUHTEMOC | E46: ALAMOS | F46: CORRESPONDE A LA FACTURA K19475. SERVICIO DE SERVIDOR VIRTUAL MENSUAL RESPALDOS EN LA NUBE Y SERVIDOR DE ACCESO A CLIENTES PARA FACTURACION JUNIO 2026 DE ESTACIONES DE ZONA NORTE. | G46: ZONA NORTE | H46: 0
A47: CEDIS Culiacán | B47: E270E3272 | C47: SRV0000467 | D47: REVOLUCION | E47: ALAMOS | F47: CORRESPONDE A LA FACTURA 3272. CONSULTORIA Y ELABORACION DOCUMENTAL DE LA STPS DEL MES DE JUNIO 2026 ZONA NORTE. | G47: ZONA NORTE | H47: 0
A48: CEDIS Mazatlán | B48: K19478 | C48: SRV0000611 | D48: Cardones | E48: Aeropuerto 1 | F48: CORRESPONDE A LA FACTURA K19478. SERVICIO DE SERVIDOR VIRTUAL MENSUAL RESPALDOS EN LA NUBE Y SERVIDOR DE ACCESO A CLIENTES PARA FACTURACION JUNIO 2026 DE ESTACIONES DE ZONA MZT 2. | G48: ZONA MZT 2 | H48: 0
A49: CEDIS Culiacán | B49: K19472 | C49: SRV0000463 | D49: HUMAYA | E49: EL DIEZ | F49: CORRESPONDE A LA FACTURA K19472. SERVICIO DE SERVIDOR VIRTUAL MENSUAL RESPALDOS EN LA NUBE Y SERVIDOR DE ACCESO A CLIENTES PARA FACTURACION JUNIO 2026 DE ESTACIONES DE ZONA CLN. | G49: ZONA CLN | H49: 0
A50: CEDIS Mazatlán | B50: K19480 | C50: SRV0000613 | D50: Munich II | E50: Juan Carrasco | F50: CORRESPONDE A LA FACTURA K19480. SERVICIO DE SERVIDOR VIRTUAL MENSUAL RESPALDOS EN LA NUBE Y SERVIDOR DE ACCESO A CLIENTES PARA FACTURACION JUNIO 2026 DE ZONA MZT 4. | G50: ZONA MZT 4 | H50: 0
A51: CEDIS Mazatlán | B51: K19479 | C51: SRV0000612 | D51: Rosario | E51: Rosario | F51: CORRESPONDE A LA FACTURA K19479. SERVICIO DE SERVIDOR VIRTUAL MENSUAL RESPALDOS EN LA NUBE Y SERVIDOR DE ACCESO A CLIENTES PARA FACTURACION JUNIO 2026 DE ESTACIONES DE ESTACION ROSARIO Y ESCUINAPA. | G51: ESCUINAPA / ROSARIO | H51: 2
A52: CEDIS Mazatlán | B52: e0b2a250 | C52: SRV0000100 | D52: Santa Rosa | E52: Cerritos | F52: PAGO A FACT. 250 POR PUBLICIDAD EN DURO Y MACIZO ESTACION CERRITOS, HABAS, PLAYAS, REAL DEL VALLE, SABALO Y MARINA, JUNIO 2026. PROGRAMAR A PAGO EL 04/05/2026 | G52: REAL DEL VALLE / CERRITOS / SABALO / MARINA / PLAYAS / LAS HABAS | H52: 6
A53: CEDIS Mazatlán | B53: A1967512 | C53: SRV0000614 | D53: Playas Del Camaron | E53: Habas | F53: CORRESPONDE A LA FACTURA 1967512-A. SERVICIO DE PAQUETERIA DE ESTACIONES HABAS, PLAYAS Y JUAN CARRASCO. | G53: CARRASCO / PLAYAS / LAS HABAS | H53: 3
A54: CEDIS Culiacán | B54: K19473 | C54: SRV0000464 | D54: ALHUEY 2 | E54: ALHUEY 1 | F54: CORRESPONDE A LA FACTURA K19473. SERVICIO DE SERVIDOR VIRTUAL MENSUAL RESPALDOS EN LA NUBE Y SERVIDOR DE ACCESO A CLIENTES PARA FACTURACION JUNIO 2026 DE ESTACIONES DE ZONA ANGOSTURA. | G54: ZONA ANGOSTURA | H54: 0
A55: Gobernador | B55: K19477 | C55: SRV0000062 | D55: ES_GOBERNADOR | E55: Administracion | F55: CORRESPONDE A LA FACTURA K19477. SERVICIO DE SERVIDOR VIRTUAL MENSUAL RESPALDOS EN LA NUBE Y SERVIDOR DE ACCESO A CLIENTES PARA FACTURACION JUNIO 2026 DE ESTACIONES DE ZONA GOBERNADOR. | G55: GOBERNADOR / ZONA GOBERNADOR | H55: 1
A56: Petroplazas Corporativo | B56: I63251 | C56: SRV0005532 | D56: ES_Corporativo | E56: CC Administracion | F56: TIMBRES FISCALES PETROPLAZAS, JUNIO 2026 | G56: ES_Corporativo | H56: 0
A57: Petroplazas Corporativo | B57: MZT3949 | C57: SRV0005534 | D57: ES_Corporativo | E57: AUTOMOVIL AU-152 | F57: SERVICIO DE LOS 180,000 KM A VEHICULO VENTO AUR-152 A CARGO DE LIC. JUAN PEDRO ROUSSE GERENTE DE VENTAS DIVISION GASOLINERAS. | G57: AU-152 | H57: 0
... A66: CEDIS Mazatlán | B66: CD6A0825 | C66: SRV0000137 | D66: Munich II | E66: Cerritos | F66: Pago a fact. o-32940 por servicio de Publicidad en programa de radio Viva la Noticia Estación Cerritos, habas, marina, Sabalo, real del valle y playas. , marzo 2026. programar a pago el 12/03/2026 | G66: REAL DEL VALLE / CERRITOS / SABALO / MARINA / PLAYAS / LAS HABAS | H66: 6
...

Sheet Distrib. Calculada
A1: Sucursal | B1: Factura | C1: Folio | D1: Grupo CC | E1: Zona / Estaciones Detectadas | F1: Total Factura (MX) | G1: Estación Distribuida | H1: % Distribución | I1: Monto Distribuido | J1: Cuenta contable
A2: Alamos | B2: A4860 | C2: SRV0000068 | D2: ES_Alamos | E2: AU-151 | F2: 249 | G2: ALAMOS | H2: 20.00% | I2: 49.8 | J2: =VLOOKUP(B2,'Datos Originales'!$D$1:$BC$462,36,FALSE) -> 50299040046
A3: Alamos | B3: A4860 | C3: SRV0000068 | D3: ES_Alamos | E3: AU-151 | F3: 249 | G3: FATIMA | H3: 20.00% | I3: 49.8 | J3: =VLOOKUP(B3,'Datos Originales'!$D$1:$BC$462,36,FALSE) -> 50299040046
A4: Alamos | B4: A4860 | C4: SRV0000068 | D4: ES_Alamos | E4: AU-151 | F4: 249 | G4: DOS VALLES | H4: 20.00% | I4: 49.8 | J4: =VLOOKUP(B4,'Datos Originales'!$D$1:$BC$462,36,FALSE) -> 50299040046
A5: Alamos | B5: A4860 | C5: SRV0000068 | D5: ES_Alamos | E5: AU-151 | F5: 249 | G5: REVOLUCION | H5: 20.00% | I5: 49.8 | J5: =VLOOKUP(B5,'Datos Originales'!$D$1:$BC$462,36,FALSE) -> 50299040046
A6: Alamos | B6: A4860 | C6: SRV0000068 | D6: ES_Alamos | E6: AU-151 | F6: 249 | G6: CUAHUTEMOC | H6: 20.00% | I6: 49.8 | J6: =VLOOKUP(B6,'Datos Originales'!$D$1:$BC$462,36,FALSE) -> 50299040046
A7: Petroplazas Corporativo | B7: 64F6E70 | C7: SRV0005503 | D7: ES_Corporativo | E7: ES_Corporativo | F7: 15724020 | G7: MARINA | H7: 2.32% | I7: 364797.27 | J7: =VLOOKUP(B7,'Datos Originales'!$D$1:$BC$462,36,FALSE) -> _CUA-DRE--000000
A8: Petroplazas Corporativo | B8: 64F6E70 | C8: SRV0005503 | D8: ES_Corporativo | E8: ES_Corporativo | F8: 15724020 | G8: SABALO | H8: 2.22% | I8: 349073.25 | J8: =VLOOKUP(B8,'Datos Originales'!$D$1:$BC$462,36,FALSE) -> _CUA-DRE--000000
A9: Petroplazas Corporativo | B9: 64F6E70 | C9: SRV0005503 | D9: ES_Corporativo | E9: ES_Corporativo | F9: 15724020 | G9: CERRITOS | H9: 2.22% | I9: 349073.25 | J9: =VLOOKUP(B9,'Datos Originales'!$D$1:$BC$462,36,FALSE) -> _CUA-DRE--000000
A10: Petroplazas Corporativo | B10: 64F6E70 | C10: SRV0005503 | D10: ES_Corporativo | E10: ES_Corporativo | F10: 15724020 | G10: REAL DEL VALLE | H10: 2.22% | I10: 349073.25 | J10: =VLOOKUP(B10,'Datos Originales'!$D$1:$BC$462,36,FALSE) -> _CUA-DRE--000000
A11: Petroplazas Corporativo | B11: 64F6E70 | C11: SRV0005503 | D11: ES_Corporativo | E11: ES_Corporativo | F11: 15724020 | G11: PLAYAS | H11: 2.22% | I11: 349073.25 | J11: =VLOOKUP(B11,'Datos Originales'!$D$1:$BC$462,36,FALSE) -> _CUA-DRE--000000
A12: Petroplazas Corporativo | B12: 64F6E70 | C12: SRV0005503 | D12: ES_Corporativo | E12: ES_Corporativo | F12: 15724020 | G12: HABAS | H12: 2.22% | I12: 349073.25 | J12: =VLOOKUP(B12,'Datos Originales'!$D$1:$BC$462,36,FALSE) -> _CUA-DRE--000000
A13: Petroplazas Corporativo | B13: 64F6E70 | C13: SRV0005503 | D13: ES_Corporativo | E13: ES_Corporativo | F13: 15724020 | G13: CARDONES | H13: 2.22% | I13: 349073.25 | J13: =VLOOKUP(B13,'Datos Originales'!$D$1:$BC$462,36,FALSE) -> _CUA-DRE--000000
... A96: Petroplazas Corporativo | B96: I40 | C96: SRV0005504 | D96: ES_Corporativo | E96: ES_Corporativo | F96: 10000 | G96: LA PAZ | H96: 2.22% | I96: 222 | J96: =VLOOKUP(B96,'Datos Originales'!$D$1:$BC$462,36,FALSE) -> 50299040021
A97: CEDIS Culiacán | B97: E018C998 | C97: E000000270 | E97: ZONA CLN | F97: 12145.48 | G97: DIEZ | H97: 10.00% | I97: 1214.55 | J97: =VLOOKUP(B97,'Datos Originales'!$D$1:$BC$462,36,FALSE) -> 20101021501
A98: CEDIS Culiacán | B98: E018C998 | C98: E000000270 | E98: ZONA CLN | F98: 12145.48 | G98: HUMAYA | H98: 8.20% | I98: 995.93 | J98: =VLOOKUP(B98,'Datos Originales'!$D$1:$BC$462,36,FALSE) -> 20101021501
A99: CEDIS Culiacán | B99: E018C998 | C99: E000000270 | E99: ZONA CLN | F99: 12145.48 | G99: BELLAVISTA | H99: 8.18% | I99: 993.5 | J99: =VLOOKUP(B99,'Datos Originales'!$D$1:$BC$462,36,FALSE) -> 20101021501
A100: CEDIS Culiacán | B100: E018C998 | C100: E000000270 | E100: ZONA CLN | F100: 12145.48 | G100: PAPALOTE | H100: 8.18% | I100: 993.5 | J100: =VLOOKUP(B100,'Datos Originales'!$D$1:$BC$462,36,FALSE) -> 20101021501
A101: CEDIS Culiacán | B101: E018C998 | C101: E000000270 | E101: ZONA CLN | F101: 12145.48 | G101: SAN PEDRO | H101: 8.18% | I101: 993.5 | J101: =VLOOKUP(B101,'Datos Originales'!$D$1:$BC$462,36,FALSE) -> 20101021501
A102: CEDIS Culiacán | B102: E018C998 | C102: E000000270 | E102: ZONA CLN | F102: 12145.48 | G102: HEROICO | H102: 8.18% | I102: 993.5 | J102: =VLOOKUP(B102,'Datos Originales'!$D$1:$BC$462,36,FALSE) -> 20101021501
A103: CEDIS Culiacán | B103: E018C998 | C103: E000000270 | E103: ZONA CLN | F103: 12145.48 | G103: MADERO | H103: 8.18% | I103: 993.5 | J103: =VLOOKUP(B103,'Datos Originales'!$D$1:$BC$462,36,FALSE) -> 20101021501
